--- Running testing.assert_series_equal#192NN/assert_series_equalNN, strategy: relancer
[ERR MSG]: OrderedDict([('project', 'testing.assert_series_equal#192NN'), ('notebook', 'assert_series_equalNN'), ('text', '  File "assert_series_equalNN.py", line 5, in <module>\n    tm.assert_series_equal(a,  b,  True,  \'equiv\', check_less_precise=False, check_datetimelike_compat=False, check_series_type=True, check_exact=False, check_names=True, check_index=True, check_like=False)\nTypeError: assert_series_equal() got an unexpected keyword argument \'check_less_precise\'\n')])
  File "assert_series_equalNN.py", line 5, in <module>
Error inducing API short name: assert_series_equal, line no: 5
Error inducing API fqn: pandas.testing.assert_series_equal, line no: 5
*** TypeError: PLACEHOLDER
Repair Action: arg_name
Key Params: ['IMPLICIT_0', 'IMPLICIT_1', 'IMPLICIT_2', 'IMPLICIT_3', 'check_less_precise', 'check_datetimelike_compat', 'check_series_type', 'check_exact', 'check_names', 'check_index', 'check_like']
Prev Params: None
Prev Repair Action: None
Line No: 5
Prev Line No: 0
GitHub Candidates:
[]
KP:['IMPLICIT_0', 'IMPLICIT_1', 'IMPLICIT_2', 'IMPLICIT_3', 'check_less_precise', 'check_datetimelike_compat', 'check_series_type', 'check_exact', 'check_names', 'check_index', 'check_like']
EXPP: ['IMPLICIT_0', 'IMPLICIT_1', 'IMPLICIT_2', 'IMPLICIT_3', 'check_less_precise', 'check_datetimelike_compat', 'check_series_type', 'check_exact', 'check_names', 'check_index', 'check_like']
APIDoc Candidates:
[]
All Solution Candidates:
[]
[INFO] This case cannot be fixed!


real	0m0.661s
user	0m1.831s
sys	0m6.450s
