--- Running testing.assert_series_equal#527NN/assert_series_equalNN, strategy: relancer
[ERR MSG]: OrderedDict([('project', 'testing.assert_series_equal#527NN'), ('notebook', 'assert_series_equalNN'), ('text', '  File "assert_series_equalNN.py", line 5, in <module>\n    tm.assert_series_equal(a, check_series_type=True, atol=1e-08, check_categorical=True, check_freq=True, check_flags=True, check_like=False, check_names=True, check_dtype=True, rtol=1e-05, check_datetimelike_compat=False, check_category_order=True, check_less_precise=False, right=b, check_index_type=\'equiv\', check_exact=False)\nTypeError: assert_series_equal() got an unexpected keyword argument \'check_less_precise\'\n')])
  File "assert_series_equalNN.py", line 5, in <module>
Error inducing API short name: assert_series_equal, line no: 5
Error inducing API fqn: pandas.testing.assert_series_equal, line no: 5
*** TypeError: PLACEHOLDER
Repair Action: arg_name
Key Params: ['IMPLICIT_0', 'check_series_type', 'atol', 'check_categorical', 'check_freq', 'check_flags', 'check_like', 'check_names', 'check_dtype', 'rtol', 'check_datetimelike_compat', 'check_category_order', 'check_less_precise', 'right', 'check_index_type', 'check_exact']
Prev Params: None
Prev Repair Action: None
Line No: 5
Prev Line No: 0
GitHub Candidates:
[]
KP:['IMPLICIT_0', 'check_series_type', 'atol', 'check_categorical', 'check_freq', 'check_flags', 'check_like', 'check_names', 'check_dtype', 'rtol', 'check_datetimelike_compat', 'check_category_order', 'check_less_precise', 'right', 'check_index_type', 'check_exact']
EXPP: ['IMPLICIT_0', 'check_series_type', 'atol', 'check_categorical', 'check_freq', 'check_flags', 'check_like', 'check_names', 'check_dtype', 'rtol', 'check_datetimelike_compat', 'check_category_order', 'check_less_precise', 'right', 'check_index_type', 'check_exact']
APIDoc Candidates:
[]
All Solution Candidates:
[]
[INFO] This case cannot be fixed!


real	0m0.665s
user	0m1.433s
sys	0m4.771s
